ERROR 2023-06-02 17:25:55,696 Internal Server Error: /news/ C:\Users\MeRKaLyuT\venv\lib\site-packages\django\utils\log.py (<class 'AttributeError'>, AttributeError("module 'datetime' has no attribute 'utcnow'"), <traceback object at 0x000001FE9A3268C0>)
Traceback (most recent call last):
  File "C:\Users\MeRKaLyuT\venv\lib\site-packages\django\core\handlers\exception.py", line 55, in inner
    response = get_response(request)
  File "C:\Users\MeRKaLyuT\venv\lib\site-packages\django\core\handlers\base.py", line 197, in _get_response
    response = wrapped_callback(request, *callback_args, **callback_kwargs)
  File "C:\Users\MeRKaLyuT\venv\lib\site-packages\django\utils\decorators.py", line 133, in _wrapped_view
    response = view_func(request, *args, **kwargs)
  File "C:\Users\MeRKaLyuT\venv\lib\site-packages\django\views\generic\base.py", line 103, in view
    return self.dispatch(request, *args, **kwargs)
  File "C:\Users\MeRKaLyuT\venv\lib\site-packages\django\views\generic\base.py", line 142, in dispatch
    return handler(request, *args, **kwargs)
  File "C:\Users\MeRKaLyuT\venv\lib\site-packages\django\views\generic\list.py", line 174, in get
    context = self.get_context_data()
  File "D:\dev\Site_0_2\NewsPaper\news\views.py", line 38, in get_context_data
    context['time_now'] = datetime.utcnow()
AttributeError: module 'datetime' has no attribute 'utcnow'
ERROR 2023-06-02 17:25:55,700 "GET /news/ HTTP/1.1" 500 89837 C:\Users\MeRKaLyuT\venv\lib\site-packages\django\core\servers\basehttp.py None
ERROR 2023-06-02 17:26:26,360 Internal Server Error: /news/ C:\Users\MeRKaLyuT\venv\lib\site-packages\django\utils\log.py (<class 'AttributeError'>, AttributeError("module 'datetime' has no attribute 'utcnow'"), <traceback object at 0x000001FE9A300E80>)
Traceback (most recent call last):
  File "C:\Users\MeRKaLyuT\venv\lib\site-packages\django\core\handlers\exception.py", line 55, in inner
    response = get_response(request)
  File "C:\Users\MeRKaLyuT\venv\lib\site-packages\django\core\handlers\base.py", line 197, in _get_response
    response = wrapped_callback(request, *callback_args, **callback_kwargs)
  File "C:\Users\MeRKaLyuT\venv\lib\site-packages\django\utils\decorators.py", line 133, in _wrapped_view
    response = view_func(request, *args, **kwargs)
  File "C:\Users\MeRKaLyuT\venv\lib\site-packages\django\views\generic\base.py", line 103, in view
    return self.dispatch(request, *args, **kwargs)
  File "C:\Users\MeRKaLyuT\venv\lib\site-packages\django\views\generic\base.py", line 142, in dispatch
    return handler(request, *args, **kwargs)
  File "C:\Users\MeRKaLyuT\venv\lib\site-packages\django\views\generic\list.py", line 174, in get
    context = self.get_context_data()
  File "D:\dev\Site_0_2\NewsPaper\news\views.py", line 38, in get_context_data
    context['time_now'] = datetime.utcnow()
AttributeError: module 'datetime' has no attribute 'utcnow'
ERROR 2023-06-02 17:26:26,363 "GET /news/ HTTP/1.1" 500 89700 C:\Users\MeRKaLyuT\venv\lib\site-packages\django\core\servers\basehttp.py None
ERROR 2023-06-02 18:22:34,423 Internal Server Error: /news/ C:\Users\MeRKaLyuT\venv\lib\site-packages\django\utils\log.py (<class 'AttributeError'>, AttributeError("module 'datetime' has no attribute 'utcnow'"), <traceback object at 0x0000029C913A40C0>)
Traceback (most recent call last):
  File "C:\Users\MeRKaLyuT\venv\lib\site-packages\django\core\handlers\exception.py", line 55, in inner
    response = get_response(request)
  File "C:\Users\MeRKaLyuT\venv\lib\site-packages\django\core\handlers\base.py", line 197, in _get_response
    response = wrapped_callback(request, *callback_args, **callback_kwargs)
  File "C:\Users\MeRKaLyuT\venv\lib\site-packages\django\utils\decorators.py", line 133, in _wrapped_view
    response = view_func(request, *args, **kwargs)
  File "C:\Users\MeRKaLyuT\venv\lib\site-packages\django\views\generic\base.py", line 103, in view
    return self.dispatch(request, *args, **kwargs)
  File "C:\Users\MeRKaLyuT\venv\lib\site-packages\django\views\generic\base.py", line 142, in dispatch
    return handler(request, *args, **kwargs)
  File "C:\Users\MeRKaLyuT\venv\lib\site-packages\django\views\generic\list.py", line 174, in get
    context = self.get_context_data()
  File "D:\dev\Site_0_2\NewsPaper\news\views.py", line 38, in get_context_data
    context['time_now'] = datetime.utcnow()
AttributeError: module 'datetime' has no attribute 'utcnow'
ERROR 2023-06-02 18:22:34,426 "GET /news/ HTTP/1.1" 500 89700 C:\Users\MeRKaLyuT\venv\lib\site-packages\django\core\servers\basehttp.py None
ERROR 2023-06-02 18:23:13,575 Internal Server Error: /news/ C:\Users\MeRKaLyuT\venv\lib\site-packages\django\utils\log.py (<class 'AttributeError'>, AttributeError("module 'datetime' has no attribute 'utcnow'"), <traceback object at 0x000001695CF81580>)
Traceback (most recent call last):
  File "C:\Users\MeRKaLyuT\venv\lib\site-packages\django\core\handlers\exception.py", line 55, in inner
    response = get_response(request)
  File "C:\Users\MeRKaLyuT\venv\lib\site-packages\django\core\handlers\base.py", line 197, in _get_response
    response = wrapped_callback(request, *callback_args, **callback_kwargs)
  File "C:\Users\MeRKaLyuT\venv\lib\site-packages\django\utils\decorators.py", line 133, in _wrapped_view
    response = view_func(request, *args, **kwargs)
  File "C:\Users\MeRKaLyuT\venv\lib\site-packages\django\views\generic\base.py", line 103, in view
    return self.dispatch(request, *args, **kwargs)
  File "C:\Users\MeRKaLyuT\venv\lib\site-packages\django\views\generic\base.py", line 142, in dispatch
    return handler(request, *args, **kwargs)
  File "C:\Users\MeRKaLyuT\venv\lib\site-packages\django\views\generic\list.py", line 174, in get
    context = self.get_context_data()
  File "D:\dev\Site_0_2\NewsPaper\news\views.py", line 38, in get_context_data
    context['time_now'] = datetime.utcnow()
AttributeError: module 'datetime' has no attribute 'utcnow'
ERROR 2023-06-02 18:23:13,579 "GET /news/ HTTP/1.1" 500 89837 C:\Users\MeRKaLyuT\venv\lib\site-packages\django\core\servers\basehttp.py None
