ERROR 2023-06-02 17:25:55,696 Internal Server Error: /news/ C:\Users\MeRKaLyuT\venv\lib\site-packages\django\utils\log.py (<class 'AttributeError'>, AttributeError("module 'datetime' has no attribute 'utcnow'"), <traceback object at 0x000001FE9A3268C0>)
Traceback (most recent call last):
  File "C:\Users\MeRKaLyuT\venv\lib\site-packages\django\core\handlers\exception.py", line 55, in inner
    response = get_response(request)
  File "C:\Users\MeRKaLyuT\venv\lib\site-packages\django\core\handlers\base.py", line 197, in _get_response
    response = wrapped_callback(request, *callback_args, **callback_kwargs)
  File "C:\Users\MeRKaLyuT\venv\lib\site-packages\django\utils\decorators.py", line 133, in _wrapped_view
    response = view_func(request, *args, **kwargs)
  File "C:\Users\MeRKaLyuT\venv\lib\site-packages\django\views\generic\base.py", line 103, in view
    return self.dispatch(request, *args, **kwargs)
  File "C:\Users\MeRKaLyuT\venv\lib\site-packages\django\views\generic\base.py", line 142, in dispatch
    return handler(request, *args, **kwargs)
  File "C:\Users\MeRKaLyuT\venv\lib\site-packages\django\views\generic\list.py", line 174, in get
    context = self.get_context_data()
  File "D:\dev\Site_0_2\NewsPaper\news\views.py", line 38, in get_context_data
    context['time_now'] = datetime.utcnow()
AttributeError: module 'datetime' has no attribute 'utcnow'
ERROR 2023-06-02 17:25:55,700 "GET /news/ HTTP/1.1" 500 89837 C:\Users\MeRKaLyuT\venv\lib\site-packages\django\core\servers\basehttp.py None
ERROR 2023-06-02 17:26:26,360 Internal Server Error: /news/ C:\Users\MeRKaLyuT\venv\lib\site-packages\django\utils\log.py (<class 'AttributeError'>, AttributeError("module 'datetime' has no attribute 'utcnow'"), <traceback object at 0x000001FE9A300E80>)
Traceback (most recent call last):
  File "C:\Users\MeRKaLyuT\venv\lib\site-packages\django\core\handlers\exception.py", line 55, in inner
    response = get_response(request)
  File "C:\Users\MeRKaLyuT\venv\lib\site-packages\django\core\handlers\base.py", line 197, in _get_response
    response = wrapped_callback(request, *callback_args, **callback_kwargs)
  File "C:\Users\MeRKaLyuT\venv\lib\site-packages\django\utils\decorators.py", line 133, in _wrapped_view
    response = view_func(request, *args, **kwargs)
  File "C:\Users\MeRKaLyuT\venv\lib\site-packages\django\views\generic\base.py", line 103, in view
    return self.dispatch(request, *args, **kwargs)
  File "C:\Users\MeRKaLyuT\venv\lib\site-packages\django\views\generic\base.py", line 142, in dispatch
    return handler(request, *args, **kwargs)
  File "C:\Users\MeRKaLyuT\venv\lib\site-packages\django\views\generic\list.py", line 174, in get
    context = self.get_context_data()
  File "D:\dev\Site_0_2\NewsPaper\news\views.py", line 38, in get_context_data
    context['time_now'] = datetime.utcnow()
AttributeError: module 'datetime' has no attribute 'utcnow'
ERROR 2023-06-02 17:26:26,363 "GET /news/ HTTP/1.1" 500 89700 C:\Users\MeRKaLyuT\venv\lib\site-packages\django\core\servers\basehttp.py None
ERROR 2023-06-02 18:22:34,423 Internal Server Error: /news/ C:\Users\MeRKaLyuT\venv\lib\site-packages\django\utils\log.py (<class 'AttributeError'>, AttributeError("module 'datetime' has no attribute 'utcnow'"), <traceback object at 0x0000029C913A40C0>)
Traceback (most recent call last):
  File "C:\Users\MeRKaLyuT\venv\lib\site-packages\django\core\handlers\exception.py", line 55, in inner
    response = get_response(request)
  File "C:\Users\MeRKaLyuT\venv\lib\site-packages\django\core\handlers\base.py", line 197, in _get_response
    response = wrapped_callback(request, *callback_args, **callback_kwargs)
  File "C:\Users\MeRKaLyuT\venv\lib\site-packages\django\utils\decorators.py", line 133, in _wrapped_view
    response = view_func(request, *args, **kwargs)
  File "C:\Users\MeRKaLyuT\venv\lib\site-packages\django\views\generic\base.py", line 103, in view
    return self.dispatch(request, *args, **kwargs)
  File "C:\Users\MeRKaLyuT\venv\lib\site-packages\django\views\generic\base.py", line 142, in dispatch
    return handler(request, *args, **kwargs)
  File "C:\Users\MeRKaLyuT\venv\lib\site-packages\django\views\generic\list.py", line 174, in get
    context = self.get_context_data()
  File "D:\dev\Site_0_2\NewsPaper\news\views.py", line 38, in get_context_data
    context['time_now'] = datetime.utcnow()
AttributeError: module 'datetime' has no attribute 'utcnow'
ERROR 2023-06-02 18:22:34,426 "GET /news/ HTTP/1.1" 500 89700 C:\Users\MeRKaLyuT\venv\lib\site-packages\django\core\servers\basehttp.py None
ERROR 2023-06-02 18:23:13,575 Internal Server Error: /news/ C:\Users\MeRKaLyuT\venv\lib\site-packages\django\utils\log.py (<class 'AttributeError'>, AttributeError("module 'datetime' has no attribute 'utcnow'"), <traceback object at 0x000001695CF81580>)
Traceback (most recent call last):
  File "C:\Users\MeRKaLyuT\venv\lib\site-packages\django\core\handlers\exception.py", line 55, in inner
    response = get_response(request)
  File "C:\Users\MeRKaLyuT\venv\lib\site-packages\django\core\handlers\base.py", line 197, in _get_response
    response = wrapped_callback(request, *callback_args, **callback_kwargs)
  File "C:\Users\MeRKaLyuT\venv\lib\site-packages\django\utils\decorators.py", line 133, in _wrapped_view
    response = view_func(request, *args, **kwargs)
  File "C:\Users\MeRKaLyuT\venv\lib\site-packages\django\views\generic\base.py", line 103, in view
    return self.dispatch(request, *args, **kwargs)
  File "C:\Users\MeRKaLyuT\venv\lib\site-packages\django\views\generic\base.py", line 142, in dispatch
    return handler(request, *args, **kwargs)
  File "C:\Users\MeRKaLyuT\venv\lib\site-packages\django\views\generic\list.py", line 174, in get
    context = self.get_context_data()
  File "D:\dev\Site_0_2\NewsPaper\news\views.py", line 38, in get_context_data
    context['time_now'] = datetime.utcnow()
AttributeError: module 'datetime' has no attribute 'utcnow'
ERROR 2023-06-02 18:23:13,579 "GET /news/ HTTP/1.1" 500 89837 C:\Users\MeRKaLyuT\venv\lib\site-packages\django\core\servers\basehttp.py None
ERROR 2023-06-02 18:31:16,912 Internal Server Error: /news/ C:\Users\MeRKaLyuT\venv\lib\site-packages\django\utils\log.py (<class 'AttributeError'>, AttributeError("module 'datetime' has no attribute 'utcnow'"), <traceback object at 0x000002195639F4C0>)
Traceback (most recent call last):
  File "C:\Users\MeRKaLyuT\venv\lib\site-packages\django\core\handlers\exception.py", line 55, in inner
    response = get_response(request)
  File "C:\Users\MeRKaLyuT\venv\lib\site-packages\django\core\handlers\base.py", line 197, in _get_response
    response = wrapped_callback(request, *callback_args, **callback_kwargs)
  File "C:\Users\MeRKaLyuT\venv\lib\site-packages\django\utils\decorators.py", line 133, in _wrapped_view
    response = view_func(request, *args, **kwargs)
  File "C:\Users\MeRKaLyuT\venv\lib\site-packages\django\views\generic\base.py", line 103, in view
    return self.dispatch(request, *args, **kwargs)
  File "C:\Users\MeRKaLyuT\venv\lib\site-packages\django\views\generic\base.py", line 142, in dispatch
    return handler(request, *args, **kwargs)
  File "C:\Users\MeRKaLyuT\venv\lib\site-packages\django\views\generic\list.py", line 174, in get
    context = self.get_context_data()
  File "D:\dev\Site_0_2\NewsPaper\news\views.py", line 38, in get_context_data
    context['time_now'] = datetime.utcnow()
AttributeError: module 'datetime' has no attribute 'utcnow'
ERROR 2023-06-02 18:31:16,916 "GET /news/ HTTP/1.1" 500 89837 C:\Users\MeRKaLyuT\venv\lib\site-packages\django\core\servers\basehttp.py None
ERROR 2023-06-03 01:17:34,736 Internal Server Error: /news/ C:\Users\MeRKaLyuT\venv\lib\site-packages\django\utils\log.py (<class 'AttributeError'>, AttributeError("module 'datetime' has no attribute 'utcnow'"), <traceback object at 0x000001BC14FE7180>)
Traceback (most recent call last):
  File "C:\Users\MeRKaLyuT\venv\lib\site-packages\django\core\handlers\exception.py", line 55, in inner
    response = get_response(request)
  File "C:\Users\MeRKaLyuT\venv\lib\site-packages\django\core\handlers\base.py", line 197, in _get_response
    response = wrapped_callback(request, *callback_args, **callback_kwargs)
  File "C:\Users\MeRKaLyuT\venv\lib\site-packages\django\utils\decorators.py", line 133, in _wrapped_view
    response = view_func(request, *args, **kwargs)
  File "C:\Users\MeRKaLyuT\venv\lib\site-packages\django\views\generic\base.py", line 103, in view
    return self.dispatch(request, *args, **kwargs)
  File "C:\Users\MeRKaLyuT\venv\lib\site-packages\django\views\generic\base.py", line 142, in dispatch
    return handler(request, *args, **kwargs)
  File "C:\Users\MeRKaLyuT\venv\lib\site-packages\django\views\generic\list.py", line 174, in get
    context = self.get_context_data()
  File "D:\dev\Problem_site_1\NewsPaper\news\views.py", line 38, in get_context_data
    context['time_now'] = datetime.utcnow()
AttributeError: module 'datetime' has no attribute 'utcnow'
ERROR 2023-06-03 01:17:34,740 "GET /news/ HTTP/1.1" 500 89904 C:\Users\MeRKaLyuT\venv\lib\site-packages\django\core\servers\basehttp.py None
ERROR 2023-06-04 11:35:51,017 Internal Server Error: /news/ C:\Users\MeRKaLyuT\venv\lib\site-packages\django\utils\log.py (<class 'AttributeError'>, AttributeError("module 'datetime' has no attribute 'utcnow'"), <traceback object at 0x000002073F2C7300>)
Traceback (most recent call last):
  File "C:\Users\MeRKaLyuT\venv\lib\site-packages\django\core\handlers\exception.py", line 55, in inner
    response = get_response(request)
  File "C:\Users\MeRKaLyuT\venv\lib\site-packages\django\core\handlers\base.py", line 197, in _get_response
    response = wrapped_callback(request, *callback_args, **callback_kwargs)
  File "C:\Users\MeRKaLyuT\venv\lib\site-packages\django\utils\decorators.py", line 133, in _wrapped_view
    response = view_func(request, *args, **kwargs)
  File "C:\Users\MeRKaLyuT\venv\lib\site-packages\django\views\generic\base.py", line 103, in view
    return self.dispatch(request, *args, **kwargs)
  File "C:\Users\MeRKaLyuT\venv\lib\site-packages\django\views\generic\base.py", line 142, in dispatch
    return handler(request, *args, **kwargs)
  File "C:\Users\MeRKaLyuT\venv\lib\site-packages\django\views\generic\list.py", line 174, in get
    context = self.get_context_data()
  File "D:\dev\Problem_site_1\NewsPaper\news\views.py", line 38, in get_context_data
    context['time_now'] = datetime.utcnow()
AttributeError: module 'datetime' has no attribute 'utcnow'
ERROR 2023-06-04 11:35:51,022 "GET /news/ HTTP/1.1" 500 90209 C:\Users\MeRKaLyuT\venv\lib\site-packages\django\core\servers\basehttp.py None
ERROR 2023-06-04 11:37:59,872 Internal Server Error: /news/ C:\Users\MeRKaLyuT\venv\lib\site-packages\django\utils\log.py (<class 'AttributeError'>, AttributeError("module 'datetime' has no attribute 'utcnow'"), <traceback object at 0x00000191B3F82940>)
Traceback (most recent call last):
  File "C:\Users\MeRKaLyuT\venv\lib\site-packages\django\core\handlers\exception.py", line 55, in inner
    response = get_response(request)
  File "C:\Users\MeRKaLyuT\venv\lib\site-packages\django\core\handlers\base.py", line 197, in _get_response
    response = wrapped_callback(request, *callback_args, **callback_kwargs)
  File "C:\Users\MeRKaLyuT\venv\lib\site-packages\django\utils\decorators.py", line 133, in _wrapped_view
    response = view_func(request, *args, **kwargs)
  File "C:\Users\MeRKaLyuT\venv\lib\site-packages\django\views\generic\base.py", line 103, in view
    return self.dispatch(request, *args, **kwargs)
  File "C:\Users\MeRKaLyuT\venv\lib\site-packages\django\views\generic\base.py", line 142, in dispatch
    return handler(request, *args, **kwargs)
  File "C:\Users\MeRKaLyuT\venv\lib\site-packages\django\views\generic\list.py", line 174, in get
    context = self.get_context_data()
  File "D:\dev\Problem_site_1\NewsPaper\news\views.py", line 38, in get_context_data
    context['time_now'] = datetime.utcnow()
AttributeError: module 'datetime' has no attribute 'utcnow'
ERROR 2023-06-04 11:37:59,877 "GET /news/ HTTP/1.1" 500 90209 C:\Users\MeRKaLyuT\venv\lib\site-packages\django\core\servers\basehttp.py None
ERROR 2023-06-04 11:39:43,930 Internal Server Error: /news/ C:\Users\MeRKaLyuT\venv\lib\site-packages\django\utils\log.py (<class 'AttributeError'>, AttributeError("module 'datetime' has no attribute 'now'"), <traceback object at 0x0000014C9CC6CCC0>)
Traceback (most recent call last):
  File "C:\Users\MeRKaLyuT\venv\lib\site-packages\django\core\handlers\exception.py", line 55, in inner
    response = get_response(request)
  File "C:\Users\MeRKaLyuT\venv\lib\site-packages\django\core\handlers\base.py", line 197, in _get_response
    response = wrapped_callback(request, *callback_args, **callback_kwargs)
  File "C:\Users\MeRKaLyuT\venv\lib\site-packages\django\utils\decorators.py", line 133, in _wrapped_view
    response = view_func(request, *args, **kwargs)
  File "C:\Users\MeRKaLyuT\venv\lib\site-packages\django\views\generic\base.py", line 103, in view
    return self.dispatch(request, *args, **kwargs)
  File "C:\Users\MeRKaLyuT\venv\lib\site-packages\django\views\generic\base.py", line 142, in dispatch
    return handler(request, *args, **kwargs)
  File "C:\Users\MeRKaLyuT\venv\lib\site-packages\django\views\generic\list.py", line 174, in get
    context = self.get_context_data()
  File "D:\dev\Problem_site_1\NewsPaper\news\views.py", line 38, in get_context_data
    context['time_now'] = datetime.now()
AttributeError: module 'datetime' has no attribute 'now'
ERROR 2023-06-04 11:39:43,936 "GET /news/ HTTP/1.1" 500 90191 C:\Users\MeRKaLyuT\venv\lib\site-packages\django\core\servers\basehttp.py None
ERROR 2023-06-04 11:39:45,651 Internal Server Error: /news/ C:\Users\MeRKaLyuT\venv\lib\site-packages\django\utils\log.py (<class 'AttributeError'>, AttributeError("module 'datetime' has no attribute 'now'"), <traceback object at 0x0000014C9CB4B780>)
Traceback (most recent call last):
  File "C:\Users\MeRKaLyuT\venv\lib\site-packages\django\core\handlers\exception.py", line 55, in inner
    response = get_response(request)
  File "C:\Users\MeRKaLyuT\venv\lib\site-packages\django\core\handlers\base.py", line 197, in _get_response
    response = wrapped_callback(request, *callback_args, **callback_kwargs)
  File "C:\Users\MeRKaLyuT\venv\lib\site-packages\django\utils\decorators.py", line 133, in _wrapped_view
    response = view_func(request, *args, **kwargs)
  File "C:\Users\MeRKaLyuT\venv\lib\site-packages\django\views\generic\base.py", line 103, in view
    return self.dispatch(request, *args, **kwargs)
  File "C:\Users\MeRKaLyuT\venv\lib\site-packages\django\views\generic\base.py", line 142, in dispatch
    return handler(request, *args, **kwargs)
  File "C:\Users\MeRKaLyuT\venv\lib\site-packages\django\views\generic\list.py", line 174, in get
    context = self.get_context_data()
  File "D:\dev\Problem_site_1\NewsPaper\news\views.py", line 38, in get_context_data
    context['time_now'] = datetime.now()
AttributeError: module 'datetime' has no attribute 'now'
ERROR 2023-06-04 11:39:45,654 "GET /news/ HTTP/1.1" 500 90191 C:\Users\MeRKaLyuT\venv\lib\site-packages\django\core\servers\basehttp.py None
ERROR 2023-06-04 11:39:54,175 Internal Server Error: /news/ C:\Users\MeRKaLyuT\venv\lib\site-packages\django\utils\log.py (<class 'AttributeError'>, AttributeError("module 'datetime' has no attribute 'utcnow'"), <traceback object at 0x0000016864A8C6C0>)
Traceback (most recent call last):
  File "C:\Users\MeRKaLyuT\venv\lib\site-packages\django\core\handlers\exception.py", line 55, in inner
    response = get_response(request)
  File "C:\Users\MeRKaLyuT\venv\lib\site-packages\django\core\handlers\base.py", line 197, in _get_response
    response = wrapped_callback(request, *callback_args, **callback_kwargs)
  File "C:\Users\MeRKaLyuT\venv\lib\site-packages\django\utils\decorators.py", line 133, in _wrapped_view
    response = view_func(request, *args, **kwargs)
  File "C:\Users\MeRKaLyuT\venv\lib\site-packages\django\views\generic\base.py", line 103, in view
    return self.dispatch(request, *args, **kwargs)
  File "C:\Users\MeRKaLyuT\venv\lib\site-packages\django\views\generic\base.py", line 142, in dispatch
    return handler(request, *args, **kwargs)
  File "C:\Users\MeRKaLyuT\venv\lib\site-packages\django\views\generic\list.py", line 174, in get
    context = self.get_context_data()
  File "D:\dev\Problem_site_1\NewsPaper\news\views.py", line 38, in get_context_data
    context['time_now'] = datetime.utcnow()
AttributeError: module 'datetime' has no attribute 'utcnow'
ERROR 2023-06-04 11:39:54,179 "GET /news/ HTTP/1.1" 500 90209 C:\Users\MeRKaLyuT\venv\lib\site-packages\django\core\servers\basehttp.py None
ERROR 2023-06-04 19:23:07,839 Internal Server Error: /news/ D:\dev\Site_0_2\venv\lib\site-packages\django\utils\log.py (<class 'AttributeError'>, AttributeError("module 'datetime' has no attribute 'utcnow'"), <traceback object at 0x000001C31062B900>)
Traceback (most recent call last):
  File "D:\dev\Site_0_2\venv\lib\site-packages\django\core\handlers\exception.py", line 55, in inner
    response = get_response(request)
  File "D:\dev\Site_0_2\venv\lib\site-packages\django\core\handlers\base.py", line 197, in _get_response
    response = wrapped_callback(request, *callback_args, **callback_kwargs)
  File "D:\dev\Site_0_2\venv\lib\site-packages\django\utils\decorators.py", line 134, in _wrapper_view
    response = view_func(request, *args, **kwargs)
  File "D:\dev\Site_0_2\venv\lib\site-packages\django\views\generic\base.py", line 104, in view
    return self.dispatch(request, *args, **kwargs)
  File "D:\dev\Site_0_2\venv\lib\site-packages\django\views\generic\base.py", line 143, in dispatch
    return handler(request, *args, **kwargs)
  File "D:\dev\Site_0_2\venv\lib\site-packages\django\views\generic\list.py", line 174, in get
    context = self.get_context_data()
  File "D:\dev\site_0_2\NewsPaper\news\views.py", line 38, in get_context_data
    context['time_now'] = datetime.utcnow()
AttributeError: module 'datetime' has no attribute 'utcnow'
ERROR 2023-06-04 19:23:07,841 "GET /news/ HTTP/1.1" 500 96044 D:\dev\Site_0_2\venv\lib\site-packages\django\core\servers\basehttp.py None
ERROR 2023-06-05 16:47:55,036 Internal Server Error: /news/ D:\dev\Site_0_2\venv\lib\site-packages\django\utils\log.py (<class 'AttributeError'>, AttributeError("module 'datetime' has no attribute 'utcnow'"), <traceback object at 0x000002B23808D240>)
Traceback (most recent call last):
  File "D:\dev\Site_0_2\venv\lib\site-packages\django\core\handlers\exception.py", line 55, in inner
    response = get_response(request)
  File "D:\dev\Site_0_2\venv\lib\site-packages\django\core\handlers\base.py", line 197, in _get_response
    response = wrapped_callback(request, *callback_args, **callback_kwargs)
  File "D:\dev\Site_0_2\venv\lib\site-packages\django\utils\decorators.py", line 134, in _wrapper_view
    response = view_func(request, *args, **kwargs)
  File "D:\dev\Site_0_2\venv\lib\site-packages\django\views\generic\base.py", line 104, in view
    return self.dispatch(request, *args, **kwargs)
  File "D:\dev\Site_0_2\venv\lib\site-packages\django\views\generic\base.py", line 143, in dispatch
    return handler(request, *args, **kwargs)
  File "D:\dev\Site_0_2\venv\lib\site-packages\django\views\generic\list.py", line 174, in get
    context = self.get_context_data()
  File "D:\dev\site_0_2\NewsPaper\news\views.py", line 38, in get_context_data
    context['time_now'] = datetime.utcnow()
AttributeError: module 'datetime' has no attribute 'utcnow'
ERROR 2023-06-05 16:47:55,038 "GET /news/ HTTP/1.1" 500 96277 D:\dev\Site_0_2\venv\lib\site-packages\django\core\servers\basehttp.py None
ERROR 2023-06-06 14:39:11,167 Internal Server Error: /news/ D:\dev\Site_0_2\venv\lib\site-packages\django\utils\log.py (<class 'django.template.exceptions.TemplateSyntaxError'>, TemplateSyntaxError("Invalid block tag on line 40: 'get_current_language'. Did you forget to register or load this tag?"), <traceback object at 0x00000270D893C240>)
Traceback (most recent call last):
  File "D:\dev\Site_0_2\venv\lib\site-packages\django\template\base.py", line 505, in parse
    compile_func = self.tags[command]
KeyError: 'get_current_language'

During handling of the above exception, another exception occurred:

Traceback (most recent call last):
  File "D:\dev\Site_0_2\venv\lib\site-packages\django\core\handlers\exception.py", line 55, in inner
    response = get_response(request)
  File "D:\dev\Site_0_2\venv\lib\site-packages\django\core\handlers\base.py", line 220, in _get_response
    response = response.render()
  File "D:\dev\Site_0_2\venv\lib\site-packages\django\template\response.py", line 114, in render
    self.content = self.rendered_content
  File "D:\dev\Site_0_2\venv\lib\site-packages\django\template\response.py", line 92, in rendered_content
    return template.render(context, self._request)
  File "D:\dev\Site_0_2\venv\lib\site-packages\django\template\backends\django.py", line 61, in render
    return self.template.render(context)
  File "D:\dev\Site_0_2\venv\lib\site-packages\django\template\base.py", line 175, in render
    return self._render(context)
  File "D:\dev\Site_0_2\venv\lib\site-packages\django\template\base.py", line 167, in _render
    return self.nodelist.render(context)
  File "D:\dev\Site_0_2\venv\lib\site-packages\django\template\base.py", line 1005, in render
    return SafeString("".join([node.render_annotated(context) for node in self]))
  File "D:\dev\Site_0_2\venv\lib\site-packages\django\template\base.py", line 1005, in <listcomp>
    return SafeString("".join([node.render_annotated(context) for node in self]))
  File "D:\dev\Site_0_2\venv\lib\site-packages\django\template\base.py", line 966, in render_annotated
    return self.render(context)
  File "D:\dev\Site_0_2\venv\lib\site-packages\django\template\loader_tags.py", line 132, in render
    compiled_parent = self.get_parent(context)
  File "D:\dev\Site_0_2\venv\lib\site-packages\django\template\loader_tags.py", line 129, in get_parent
    return self.find_template(parent, context)
  File "D:\dev\Site_0_2\venv\lib\site-packages\django\template\loader_tags.py", line 107, in find_template
    template, origin = context.template.engine.find_template(
  File "D:\dev\Site_0_2\venv\lib\site-packages\django\template\engine.py", line 157, in find_template
    template = loader.get_template(name, skip=skip)
  File "D:\dev\Site_0_2\venv\lib\site-packages\django\template\loaders\cached.py", line 57, in get_template
    template = super().get_template(template_name, skip)
  File "D:\dev\Site_0_2\venv\lib\site-packages\django\template\loaders\base.py", line 28, in get_template
    return Template(
  File "D:\dev\Site_0_2\venv\lib\site-packages\django\template\base.py", line 154, in __init__
    self.nodelist = self.compile_nodelist()
  File "D:\dev\Site_0_2\venv\lib\site-packages\django\template\base.py", line 200, in compile_nodelist
    return parser.parse()
  File "D:\dev\Site_0_2\venv\lib\site-packages\django\template\base.py", line 507, in parse
    self.invalid_block_tag(token, command, parse_until)
  File "D:\dev\Site_0_2\venv\lib\site-packages\django\template\base.py", line 568, in invalid_block_tag
    raise self.error(
django.template.exceptions.TemplateSyntaxError: Invalid block tag on line 40: 'get_current_language'. Did you forget to register or load this tag?
ERROR 2023-06-06 14:39:11,171 "GET /news/ HTTP/1.1" 500 195954 D:\dev\Site_0_2\venv\lib\site-packages\django\core\servers\basehttp.py None
ERROR 2023-06-07 23:05:56,372 "GET /news/?title__icontains=&category_type=&added_after= HTTP/1.1" 500 59 D:\dev\Site_0_2\venv\lib\site-packages\django\core\servers\basehttp.py None
ERROR 2023-06-07 23:06:10,903 "GET /news/?title__icontains=&category_type=&added_after= HTTP/1.1" 500 59 D:\dev\Site_0_2\venv\lib\site-packages\django\core\servers\basehttp.py None
ERROR 2023-06-08 15:32:07,955 Internal Server Error: /admin/news/post/ D:\dev\Site_0_2\venv\lib\site-packages\django\utils\log.py (<class 'django.db.utils.OperationalError'>, OperationalError('no such column: news_post.title_en_us'), <traceback object at 0x000002675CC57340>)
Traceback (most recent call last):
  File "D:\dev\Site_0_2\venv\lib\site-packages\django\db\backends\utils.py", line 89, in _execute
    return self.cursor.execute(sql, params)
  File "D:\dev\Site_0_2\venv\lib\site-packages\django\db\backends\sqlite3\base.py", line 328, in execute
    return super().execute(query, params)
sqlite3.OperationalError: no such column: news_post.title_en_us

The above exception was the direct cause of the following exception:

Traceback (most recent call last):
  File "D:\dev\Site_0_2\venv\lib\site-packages\django\core\handlers\exception.py", line 55, in inner
    response = get_response(request)
  File "D:\dev\Site_0_2\venv\lib\site-packages\django\core\handlers\base.py", line 197, in _get_response
    response = wrapped_callback(request, *callback_args, **callback_kwargs)
  File "D:\dev\Site_0_2\venv\lib\site-packages\django\contrib\admin\options.py", line 688, in wrapper
    return self.admin_site.admin_view(view)(*args, **kwargs)
  File "D:\dev\Site_0_2\venv\lib\site-packages\django\utils\decorators.py", line 134, in _wrapper_view
    response = view_func(request, *args, **kwargs)
  File "D:\dev\Site_0_2\venv\lib\site-packages\django\views\decorators\cache.py", line 62, in _wrapper_view_func
    response = view_func(request, *args, **kwargs)
  File "D:\dev\Site_0_2\venv\lib\site-packages\django\contrib\admin\sites.py", line 242, in inner
    return view(request, *args, **kwargs)
  File "D:\dev\Site_0_2\venv\lib\site-packages\django\utils\decorators.py", line 46, in _wrapper
    return bound_method(*args, **kwargs)
  File "D:\dev\Site_0_2\venv\lib\site-packages\django\utils\decorators.py", line 134, in _wrapper_view
    response = view_func(request, *args, **kwargs)
  File "D:\dev\Site_0_2\venv\lib\site-packages\django\contrib\admin\options.py", line 2065, in changelist_view
    "selection_note": _("0 of %(cnt)s selected") % {"cnt": len(cl.result_list)},
  File "D:\dev\Site_0_2\venv\lib\site-packages\django\db\models\query.py", line 380, in __len__
    self._fetch_all()
  File "D:\dev\Site_0_2\venv\lib\site-packages\django\db\models\query.py", line 1881, in _fetch_all
    self._result_cache = list(self._iterable_class(self))
  File "D:\dev\Site_0_2\venv\lib\site-packages\django\db\models\query.py", line 91, in __iter__
    results = compiler.execute_sql(
  File "D:\dev\Site_0_2\venv\lib\site-packages\django\db\models\sql\compiler.py", line 1560, in execute_sql
    cursor.execute(sql, params)
  File "D:\dev\Site_0_2\venv\lib\site-packages\django\db\backends\utils.py", line 102, in execute
    return super().execute(sql, params)
  File "D:\dev\Site_0_2\venv\lib\site-packages\django\db\backends\utils.py", line 67, in execute
    return self._execute_with_wrappers(
  File "D:\dev\Site_0_2\venv\lib\site-packages\django\db\backends\utils.py", line 80, in _execute_with_wrappers
    return executor(sql, params, many, context)
  File "D:\dev\Site_0_2\venv\lib\site-packages\django\db\backends\utils.py", line 84, in _execute
    with self.db.wrap_database_errors:
  File "D:\dev\Site_0_2\venv\lib\site-packages\django\db\utils.py", line 91, in __exit__
    raise dj_exc_value.with_traceback(traceback) from exc_value
  File "D:\dev\Site_0_2\venv\lib\site-packages\django\db\backends\utils.py", line 89, in _execute
    return self.cursor.execute(sql, params)
  File "D:\dev\Site_0_2\venv\lib\site-packages\django\db\backends\sqlite3\base.py", line 328, in execute
    return super().execute(query, params)
django.db.utils.OperationalError: no such column: news_post.title_en_us
ERROR 2023-06-08 15:32:07,960 "GET /admin/news/post/ HTTP/1.1" 500 166807 D:\dev\Site_0_2\venv\lib\site-packages\django\core\servers\basehttp.py None
ERROR 2023-06-08 15:32:49,872 "GET /news/?title__icontains=&category_type=&added_after= HTTP/1.1" 500 59 D:\dev\Site_0_2\venv\lib\site-packages\django\core\servers\basehttp.py None
ERROR 2023-06-08 15:37:01,501 Internal Server Error: /news/ D:\dev\Site_0_2\venv\lib\site-packages\django\utils\log.py (<class 'django.db.utils.OperationalError'>, OperationalError('no such table: news_post'), <traceback object at 0x000001197D8480C0>)
Traceback (most recent call last):
  File "D:\dev\Site_0_2\venv\lib\site-packages\django\db\backends\utils.py", line 89, in _execute
    return self.cursor.execute(sql, params)
  File "D:\dev\Site_0_2\venv\lib\site-packages\django\db\backends\sqlite3\base.py", line 328, in execute
    return super().execute(query, params)
sqlite3.OperationalError: no such table: news_post

The above exception was the direct cause of the following exception:

Traceback (most recent call last):
  File "D:\dev\Site_0_2\venv\lib\site-packages\django\core\handlers\exception.py", line 55, in inner
    response = get_response(request)
  File "D:\dev\Site_0_2\venv\lib\site-packages\django\core\handlers\base.py", line 197, in _get_response
    response = wrapped_callback(request, *callback_args, **callback_kwargs)
  File "D:\dev\Site_0_2\venv\lib\site-packages\django\utils\decorators.py", line 134, in _wrapper_view
    response = view_func(request, *args, **kwargs)
  File "D:\dev\Site_0_2\venv\lib\site-packages\django\views\generic\base.py", line 104, in view
    return self.dispatch(request, *args, **kwargs)
  File "D:\dev\Site_0_2\venv\lib\site-packages\django\views\generic\base.py", line 143, in dispatch
    return handler(request, *args, **kwargs)
  File "D:\dev\Site_0_2\venv\lib\site-packages\django\views\generic\list.py", line 174, in get
    context = self.get_context_data()
  File "D:\dev\site_0_2\NewsPaper\news\views.py", line 38, in get_context_data
    context = super().get_context_data(**kwargs)
  File "D:\dev\Site_0_2\venv\lib\site-packages\django\views\generic\list.py", line 128, in get_context_data
    paginator, page, queryset, is_paginated = self.paginate_queryset(
  File "D:\dev\Site_0_2\venv\lib\site-packages\django\views\generic\list.py", line 73, in paginate_queryset
    page = paginator.page(page_number)
  File "D:\dev\Site_0_2\venv\lib\site-packages\django\core\paginator.py", line 72, in page
    number = self.validate_number(number)
  File "D:\dev\Site_0_2\venv\lib\site-packages\django\core\paginator.py", line 53, in validate_number
    if number > self.num_pages:
  File "D:\dev\Site_0_2\venv\lib\site-packages\django\utils\functional.py", line 57, in __get__
    res = instance.__dict__[self.name] = self.func(instance)
  File "D:\dev\Site_0_2\venv\lib\site-packages\django\core\paginator.py", line 99, in num_pages
    if self.count == 0 and not self.allow_empty_first_page:
  File "D:\dev\Site_0_2\venv\lib\site-packages\django\utils\functional.py", line 57, in __get__
    res = instance.__dict__[self.name] = self.func(instance)
  File "D:\dev\Site_0_2\venv\lib\site-packages\django\core\paginator.py", line 93, in count
    return c()
  File "D:\dev\Site_0_2\venv\lib\site-packages\django\db\models\query.py", line 608, in count
    return self.query.get_count(using=self.db)
  File "D:\dev\Site_0_2\venv\lib\site-packages\django\db\models\sql\query.py", line 539, in get_count
    return obj.get_aggregation(using, {"__count": Count("*")})["__count"]
  File "D:\dev\Site_0_2\venv\lib\site-packages\django\db\models\sql\query.py", line 525, in get_aggregation
    result = compiler.execute_sql(SINGLE)
  File "D:\dev\Site_0_2\venv\lib\site-packages\django\db\models\sql\compiler.py", line 1560, in execute_sql
    cursor.execute(sql, params)
  File "D:\dev\Site_0_2\venv\lib\site-packages\django\db\backends\utils.py", line 102, in execute
    return super().execute(sql, params)
  File "D:\dev\Site_0_2\venv\lib\site-packages\django\db\backends\utils.py", line 67, in execute
    return self._execute_with_wrappers(
  File "D:\dev\Site_0_2\venv\lib\site-packages\django\db\backends\utils.py", line 80, in _execute_with_wrappers
    return executor(sql, params, many, context)
  File "D:\dev\Site_0_2\venv\lib\site-packages\django\db\backends\utils.py", line 84, in _execute
    with self.db.wrap_database_errors:
  File "D:\dev\Site_0_2\venv\lib\site-packages\django\db\utils.py", line 91, in __exit__
    raise dj_exc_value.with_traceback(traceback) from exc_value
  File "D:\dev\Site_0_2\venv\lib\site-packages\django\db\backends\utils.py", line 89, in _execute
    return self.cursor.execute(sql, params)
  File "D:\dev\Site_0_2\venv\lib\site-packages\django\db\backends\sqlite3\base.py", line 328, in execute
    return super().execute(query, params)
django.db.utils.OperationalError: no such table: news_post
ERROR 2023-06-08 15:37:01,508 "GET /news/?title__icontains=&category_type=&added_after= HTTP/1.1" 500 185496 D:\dev\Site_0_2\venv\lib\site-packages\django\core\servers\basehttp.py None
ERROR 2023-06-08 17:11:16,851 Internal Server Error: /admin/news/post/ D:\dev\Site_0_2\venv\lib\site-packages\django\utils\log.py (<class 'django.db.utils.OperationalError'>, OperationalError('no such table: news_post'), <traceback object at 0x0000020FEBA37E40>)
Traceback (most recent call last):
  File "D:\dev\Site_0_2\venv\lib\site-packages\django\db\backends\utils.py", line 89, in _execute
    return self.cursor.execute(sql, params)
  File "D:\dev\Site_0_2\venv\lib\site-packages\django\db\backends\sqlite3\base.py", line 328, in execute
    return super().execute(query, params)
sqlite3.OperationalError: no such table: news_post

The above exception was the direct cause of the following exception:

Traceback (most recent call last):
  File "D:\dev\Site_0_2\venv\lib\site-packages\django\core\handlers\exception.py", line 55, in inner
    response = get_response(request)
  File "D:\dev\Site_0_2\venv\lib\site-packages\django\core\handlers\base.py", line 197, in _get_response
    response = wrapped_callback(request, *callback_args, **callback_kwargs)
  File "D:\dev\Site_0_2\venv\lib\site-packages\django\contrib\admin\options.py", line 688, in wrapper
    return self.admin_site.admin_view(view)(*args, **kwargs)
  File "D:\dev\Site_0_2\venv\lib\site-packages\django\utils\decorators.py", line 134, in _wrapper_view
    response = view_func(request, *args, **kwargs)
  File "D:\dev\Site_0_2\venv\lib\site-packages\django\views\decorators\cache.py", line 62, in _wrapper_view_func
    response = view_func(request, *args, **kwargs)
  File "D:\dev\Site_0_2\venv\lib\site-packages\django\contrib\admin\sites.py", line 242, in inner
    return view(request, *args, **kwargs)
  File "D:\dev\Site_0_2\venv\lib\site-packages\django\utils\decorators.py", line 46, in _wrapper
    return bound_method(*args, **kwargs)
  File "D:\dev\Site_0_2\venv\lib\site-packages\django\utils\decorators.py", line 134, in _wrapper_view
    response = view_func(request, *args, **kwargs)
  File "D:\dev\Site_0_2\venv\lib\site-packages\django\contrib\admin\options.py", line 1926, in changelist_view
    cl = self.get_changelist_instance(request)
  File "D:\dev\Site_0_2\venv\lib\site-packages\django\contrib\admin\options.py", line 836, in get_changelist_instance
    return ChangeList(
  File "D:\dev\Site_0_2\venv\lib\site-packages\django\contrib\admin\views\main.py", line 123, in __init__
    self.get_results(request)
  File "D:\dev\Site_0_2\venv\lib\site-packages\django\contrib\admin\views\main.py", line 279, in get_results
    result_count = paginator.count
  File "D:\dev\Site_0_2\venv\lib\site-packages\django\utils\functional.py", line 57, in __get__
    res = instance.__dict__[self.name] = self.func(instance)
  File "D:\dev\Site_0_2\venv\lib\site-packages\django\core\paginator.py", line 93, in count
    return c()
  File "D:\dev\Site_0_2\venv\lib\site-packages\django\db\models\query.py", line 608, in count
    return self.query.get_count(using=self.db)
  File "D:\dev\Site_0_2\venv\lib\site-packages\django\db\models\sql\query.py", line 539, in get_count
    return obj.get_aggregation(using, {"__count": Count("*")})["__count"]
  File "D:\dev\Site_0_2\venv\lib\site-packages\django\db\models\sql\query.py", line 525, in get_aggregation
    result = compiler.execute_sql(SINGLE)
  File "D:\dev\Site_0_2\venv\lib\site-packages\django\db\models\sql\compiler.py", line 1560, in execute_sql
    cursor.execute(sql, params)
  File "D:\dev\Site_0_2\venv\lib\site-packages\django\db\backends\utils.py", line 102, in execute
    return super().execute(sql, params)
  File "D:\dev\Site_0_2\venv\lib\site-packages\django\db\backends\utils.py", line 67, in execute
    return self._execute_with_wrappers(
  File "D:\dev\Site_0_2\venv\lib\site-packages\django\db\backends\utils.py", line 80, in _execute_with_wrappers
    return executor(sql, params, many, context)
  File "D:\dev\Site_0_2\venv\lib\site-packages\django\db\backends\utils.py", line 84, in _execute
    with self.db.wrap_database_errors:
  File "D:\dev\Site_0_2\venv\lib\site-packages\django\db\utils.py", line 91, in __exit__
    raise dj_exc_value.with_traceback(traceback) from exc_value
  File "D:\dev\Site_0_2\venv\lib\site-packages\django\db\backends\utils.py", line 89, in _execute
    return self.cursor.execute(sql, params)
  File "D:\dev\Site_0_2\venv\lib\site-packages\django\db\backends\sqlite3\base.py", line 328, in execute
    return super().execute(query, params)
django.db.utils.OperationalError: no such table: news_post
ERROR 2023-06-08 17:11:16,865 "GET /admin/news/post/ HTTP/1.1" 500 185365 D:\dev\Site_0_2\venv\lib\site-packages\django\core\servers\basehttp.py None
ERROR 2023-06-08 21:18:10,796 Internal Server Error: /admin/news/post/ D:\dev\Site_0_2\venv\lib\site-packages\django\utils\log.py (<class 'django.db.utils.OperationalError'>, OperationalError('no such table: news_post'), <traceback object at 0x000001F7C8711380>)
Traceback (most recent call last):
  File "D:\dev\Site_0_2\venv\lib\site-packages\django\db\backends\utils.py", line 89, in _execute
    return self.cursor.execute(sql, params)
  File "D:\dev\Site_0_2\venv\lib\site-packages\django\db\backends\sqlite3\base.py", line 328, in execute
    return super().execute(query, params)
sqlite3.OperationalError: no such table: news_post

The above exception was the direct cause of the following exception:

Traceback (most recent call last):
  File "D:\dev\Site_0_2\venv\lib\site-packages\django\core\handlers\exception.py", line 55, in inner
    response = get_response(request)
  File "D:\dev\Site_0_2\venv\lib\site-packages\django\core\handlers\base.py", line 197, in _get_response
    response = wrapped_callback(request, *callback_args, **callback_kwargs)
  File "D:\dev\Site_0_2\venv\lib\site-packages\django\contrib\admin\options.py", line 688, in wrapper
    return self.admin_site.admin_view(view)(*args, **kwargs)
  File "D:\dev\Site_0_2\venv\lib\site-packages\django\utils\decorators.py", line 134, in _wrapper_view
    response = view_func(request, *args, **kwargs)
  File "D:\dev\Site_0_2\venv\lib\site-packages\django\views\decorators\cache.py", line 62, in _wrapper_view_func
    response = view_func(request, *args, **kwargs)
  File "D:\dev\Site_0_2\venv\lib\site-packages\django\contrib\admin\sites.py", line 242, in inner
    return view(request, *args, **kwargs)
  File "D:\dev\Site_0_2\venv\lib\site-packages\django\utils\decorators.py", line 46, in _wrapper
    return bound_method(*args, **kwargs)
  File "D:\dev\Site_0_2\venv\lib\site-packages\django\utils\decorators.py", line 134, in _wrapper_view
    response = view_func(request, *args, **kwargs)
  File "D:\dev\Site_0_2\venv\lib\site-packages\django\contrib\admin\options.py", line 1926, in changelist_view
    cl = self.get_changelist_instance(request)
  File "D:\dev\Site_0_2\venv\lib\site-packages\django\contrib\admin\options.py", line 836, in get_changelist_instance
    return ChangeList(
  File "D:\dev\Site_0_2\venv\lib\site-packages\django\contrib\admin\views\main.py", line 123, in __init__
    self.get_results(request)
  File "D:\dev\Site_0_2\venv\lib\site-packages\django\contrib\admin\views\main.py", line 279, in get_results
    result_count = paginator.count
  File "D:\dev\Site_0_2\venv\lib\site-packages\django\utils\functional.py", line 57, in __get__
    res = instance.__dict__[self.name] = self.func(instance)
  File "D:\dev\Site_0_2\venv\lib\site-packages\django\core\paginator.py", line 93, in count
    return c()
  File "D:\dev\Site_0_2\venv\lib\site-packages\django\db\models\query.py", line 608, in count
    return self.query.get_count(using=self.db)
  File "D:\dev\Site_0_2\venv\lib\site-packages\django\db\models\sql\query.py", line 539, in get_count
    return obj.get_aggregation(using, {"__count": Count("*")})["__count"]
  File "D:\dev\Site_0_2\venv\lib\site-packages\django\db\models\sql\query.py", line 525, in get_aggregation
    result = compiler.execute_sql(SINGLE)
  File "D:\dev\Site_0_2\venv\lib\site-packages\django\db\models\sql\compiler.py", line 1560, in execute_sql
    cursor.execute(sql, params)
  File "D:\dev\Site_0_2\venv\lib\site-packages\django\db\backends\utils.py", line 102, in execute
    return super().execute(sql, params)
  File "D:\dev\Site_0_2\venv\lib\site-packages\django\db\backends\utils.py", line 67, in execute
    return self._execute_with_wrappers(
  File "D:\dev\Site_0_2\venv\lib\site-packages\django\db\backends\utils.py", line 80, in _execute_with_wrappers
    return executor(sql, params, many, context)
  File "D:\dev\Site_0_2\venv\lib\site-packages\django\db\backends\utils.py", line 84, in _execute
    with self.db.wrap_database_errors:
  File "D:\dev\Site_0_2\venv\lib\site-packages\django\db\utils.py", line 91, in __exit__
    raise dj_exc_value.with_traceback(traceback) from exc_value
  File "D:\dev\Site_0_2\venv\lib\site-packages\django\db\backends\utils.py", line 89, in _execute
    return self.cursor.execute(sql, params)
  File "D:\dev\Site_0_2\venv\lib\site-packages\django\db\backends\sqlite3\base.py", line 328, in execute
    return super().execute(query, params)
django.db.utils.OperationalError: no such table: news_post
ERROR 2023-06-08 21:18:10,802 "GET /admin/news/post/ HTTP/1.1" 500 185365 D:\dev\Site_0_2\venv\lib\site-packages\django\core\servers\basehttp.py None
